Traceback (most recent call last):
  File "raise.py", line 1, in <module>
    raise Exception('Bad value')
Exception: Bad value